<?xml version="1.0" ?>
<robot name="lidar3d" xmlns:xacro="http://www.ros.org/wiki/xacro">

	<gazebo>
		<plugin name="gazebo_ros_control" filename="libgazebo_ros_control.so">
			<robotNamespace>/lidar3d</robotNamespace>
			<robotSimType>gazebo_ros_control/DefaultRobotHWSim</robotSimType>
			<legacyModeNS>true</legacyModeNS>
		</plugin>
  	</gazebo>

	<material name="black">
		<color rgba="0.0 0.0 0.0 1.0"/>
	</material>
	<material name="grey">
		<color rgba="0.4 0.4 0.4 1.0"/>
	</material>

<!-- Used for fixing robot to Gazebo 'base_link' -->
	<link name="world"/>
	<joint name="fixed_gazebo" type="fixed">
		<parent link="world"/>
		<child link="base"/>
	</joint>


	<link name="base"/>
	<joint name="fixed" type="fixed">
		<parent link="base"/>
		<child link="link1"/>
	</joint>
<!-- This is the base for which the unit rotatoes on -->
	<link name="link1">
		<collision>
			<origin xyz="0 0 0.025" rpy="0 0 0"/>
			<geometry>
				<cylinder radius="0.075" length="0.05"/>
			</geometry>
		</collision>
		<visual>
			<origin xyz="0 0 0.025" rpy="0 0 0"/>
			<geometry>
				<cylinder radius="0.05" length="0.05"/>
			</geometry>
			<material name="black"/>
		</visual>
		<inertial>
			<origin xyz="0 0 0.025" rpy="0 0 0"/>
			<mass value="1"/>
			<inertia ixx="1.0" ixy="0.0" ixz="0.0" iyy="1.0" iyz="0.0" izz="1.0"/>
		</inertial>
	</link>
<!-- This is the joint that rotates the top half -->
	<joint name="joint1" type="continuous">
		<parent link="link1"/>
		<child link="link2"/>
		<origin xyz="0 0 0.052" rpy="0 0 0"/>
		<axis xyz="0 0 1"/>
	</joint>

	<transmission name="tran1">
		<type>transmission_interface/SimpleTransmission</type>
		<joint name="joint1">
			<hardwareInterface>hardware_interface/EffortJointInterface</hardwareInterface>
		</joint>
		<actuator name="motor1">
			<hardwareInterface>hardware_interface/EffortJointInterface</hardwareInterface>
			<mechanicalReduction>1</mechanicalReduction>
		</actuator>
	</transmission>
<!-- This is the cylindrical shaft that elevates the two lidars -->
	<link name="link2">
		<collision>
			<origin xyz="0 0 0.048" rpy="0 0 0"/>
			<geometry>
				<cylinder radius="0.045" length="0.1"/>
			</geometry>
		</collision>
		<visual>
			<origin xyz="0 0 0.048" rpy="0 0 0"/>
			<geometry>
				<cylinder radius="0.045" length="0.1"/>
			</geometry>
			<material name="grey"/>
		</visual>
		<inertial>
			<origin xyz="0 0 0.048" rpy="0 0 0"/>
			<mass value="1"/>
			<inertia ixx="1.0" ixy="0.0" ixz="0.0" iyy="1.0" iyz="0.0" izz="1.0"/>
		</inertial>
	</link>
<!-- This is a rigid link (glue) that affixes a perpendicular cylinder for the lidars
	 to fluch-mount to -->
	<joint name="joint2" type="fixed">
		<parent link="link2"/>
		<child link="link3"/>
		<origin xyz="0 0 0.1" rpy="0 0 0"/>
		<axis xyz="0 0 1"/>
	</joint>
<!-- This is the aforementioned perpendicular cylinder -->
	<link name="link3">
		<collision>
			<origin xyz="0 0 0" rpy="0 1.5708 0"/>
			<geometry>
				<cylinder radius="0.05" length="0.1"/>
			</geometry>
		</collision>
		<visual>
			<origin xyz="0 0 0" rpy="0 1.5708 0"/>
			<geometry>
				<cylinder radius="0.05" length="0.1"/>
			</geometry>
			<material name="grey"/>
		</visual>
		<inertial>
			<origin xyz="0 0 0" rpy="0 1.5708 0"/>
			<mass value="1"/>
			<inertia ixx="1.0" ixy="0.0" ixz="0.0" iyy="1.0" iyz="0.0" izz="1.0"/>
		</inertial>
	</link>

<!-- These next two joints affix the two lidar units to opposite ends of the 
    perpendicular cylinder -->
	<joint name="joint3" type="fixed">
		<parent link="link3"/>
		<child link="base_laser1"/>
		<origin xyz="0.05 0 0" rpy="0 -1.5708 3.14"/>
		<axis xyz="0 0 1"/>
	</joint>

	<joint name="joint4" type="fixed">
		<parent link="link3"/>
		<child link="base_laser2"/>
		<origin xyz="-0.05 0 0" rpy="0 -1.5708 0"/>
		<axis xyz="0 0 1"/>
	</joint> 

<!-- The following link-joint-link tags belong to the first YG-LiDAR unit -->
	<link name="base_laser1">
    	<inertial>
      		<origin xyz="-0.00029774 0.0066667 0.00013047" rpy="0 0 0" />
			<mass value="0.15717" />
			<inertia ixx="6.7885E-05" ixy="-1.3987E-07" ixz="-8.1554E-07" iyy="0.00013173" iyz="-9.0932E-08" izz="7.1972E-05" />
		</inertial>
    	<visual>
			<origin xyz="0 0 0" rpy="0 0 0" />
			<geometry>
				<mesh filename="package://frame_trans/meshes/ydlidar.dae" />
			</geometry>
			<material name="">
				<color rgba="0.64706 0.61961 0.58824 1" />
			</material>
		</visual>
		<collision>
			<origin xyz="0 0 0" rpy="0 0 0" />
			<geometry>
				<mesh filename="package://frame_trans/meshes/ydlidar.dae" />
			</geometry>
		</collision>
	</link>

	<link
		name="laser_frame1">
		<inertial>
			<origin xyz="-0.00036659 0.00064155 -0.00027052" rpy="0 0 0" />
			<mass value="0.25482" />
			<inertia ixx="8.9194E-05" ixy="1.8116E-07" ixz="3.6435E-08" iyy="0.00018279" iyz="2.423E-07" izz="0.00011103" />
		</inertial>
	</link>
<!-- Making this fixed prevents rotation in rviz -->
	<joint name="laser_joint1" type="fixed">
		<origin xyz="0 0 0.03172" rpy="0 0 0" />
		<parent link="base_laser1" />
		<child link="laser_frame1" />
		<axis xyz="0 0 1" />
	</joint>

<!-- The following link-joint-link tags belong to the second YG-LiDAR -->
	<link name="base_laser2">
    	<inertial>
      		<origin xyz="-0.00029774 0.0066667 0.00013047" rpy="0 0 0" />
			<mass value="0.15717" />
			<inertia ixx="6.7885E-05" ixy="-1.3987E-07" ixz="-8.1554E-07" iyy="0.00013173" iyz="-9.0932E-08" izz="7.1972E-05" />
		</inertial>
    	<visual>
			<origin xyz="0 0 0" rpy="0 0 0" />
			<geometry>
				<mesh filename="package://frame_trans/meshes/ydlidar.dae" />
			</geometry>
			<material name="">
				<color rgba="0.64706 0.61961 0.58824 1" />
			</material>
		</visual>
		<collision>
			<origin xyz="0 0 0" rpy="0 0 0" />
			<geometry>
				<mesh filename="package://frame_trans/meshes/ydlidar.dae" />
			</geometry>
		</collision>
	</link>

	<link
		name="laser_frame2">
		<inertial>
			<origin xyz="-0.00036659 0.00064155 -0.00027052" rpy="0 0 0" />
			<mass value="0.25482" />
			<inertia ixx="8.9194E-05" ixy="1.8116E-07" ixz="3.6435E-08" iyy="0.00018279" iyz="2.423E-07" izz="0.00011103" />
		</inertial>
	</link>

	<joint name="laser_joint2" type="fixed">
		<origin xyz="0 0 0.03172" rpy="0 0 0" />
		<parent link="base_laser2" />
		<child link="laser_frame2" />
		<axis xyz="0 0 1" />
	</joint>

<!-- This next section has the laser sensor tag -->
	<gazebo reference="laser_frame1">
		<sensor type="ray" name="sensor1">
			<pose>0 0 0 0 0 0</pose>
			<visualize>true</visualize>
			<update_rate>12</update_rate>
			<ray>
				<scan>
					<horizontal>
						<samples>750</samples>
						<resolution>1</resolution>
						<min_angle>-3.14159</min_angle>
						<max_angle>3.14159</max_angle>
					</horizontal>
				</scan>
				<range>
					<min>0.10</min>
					<max>40.0</max>
					<resolution>0.01</resolution>
				</range>
				<noise>
					<type>gaussian</type>
					<!-- Noise parameters based on published spec for Hokuyo laser
						achieving "+-30mm" accuracy at range < 10m.  A mean of 0.0m and
						stddev of 0.01m will put 99.7% of samples within 0.03m of the true
						reading. -->
					<mean>0.0</mean>
					<stddev>0.01</stddev>
				</noise>
			</ray>
			<plugin name="gazebo_ros_head_hokuyo_controller" filename="libgazebo_ros_laser.so">
				<topicName>/lidar3d/laser/scan1</topicName>
				<frameName>laser_frame1</frameName>
			</plugin>
		</sensor>
	</gazebo>

	<gazebo reference="laser_frame2">
		<sensor type="ray" name="sensor2">
			<pose>0 0 0 0 0 0</pose>
			<visualize>true</visualize>
			<update_rate>12</update_rate>
			<ray>
				<scan>
					<horizontal>
						<samples>750</samples>
						<resolution>1</resolution>
						<min_angle>-3.14159</min_angle>
						<max_angle>3.14159</max_angle>
					</horizontal>
				</scan>
				<range>
					<min>0.10</min>
					<max>40.0</max>
					<resolution>0.01</resolution>
				</range>
				<noise>
					<type>gaussian</type>
					<!-- Noise parameters based on published spec for Hokuyo laser
						achieving "+-30mm" accuracy at range < 10m.  A mean of 0.0m and
						stddev of 0.01m will put 99.7% of samples within 0.03m of the true
						reading. -->
					<mean>0.0</mean>
					<stddev>0.01</stddev>
				</noise>
			</ray>
			<plugin name="gazebo_ros_head_hokuyo_controller" filename="libgazebo_ros_laser.so">
				<topicName>/lidar3d/laser/scan2</topicName>
				<frameName>laser_frame2</frameName>
			</plugin>
		</sensor>
	</gazebo>

</robot>
